2022-02-14 10:15:41 CET:grace_p2p_client:ERROR:fatal error
Traceback (most recent call last):
  File "../tools/grace_p2p_client.py", line 536, in <module>
    unit_test2()
  File "../tools/grace_p2p_client.py", line 502, in unit_test2
    bot = P2PBot(config)
TypeError: __init__() takes 1 positional argument but 2 were given
