2022-02-10 14:22:01 CET:grace_p2p_client:INFO:loading ctx from store.json
2022-02-10 14:22:01 CET:grace_p2p_client:ERROR:fatal error
Traceback (most recent call last):
  File "../tools/grace_p2p_client.py", line 489, in <module>
    emulate()
  File "../tools/grace_p2p_client.py", line 468, in emulate
    bot = P2PBot()
  File "../tools/grace_p2p_client.py", line 167, in __init__
    self.store = json.load(outfile)
  File "/usr/lib/python3.8/json/__init__.py", line 293, in load
    return loads(fp.read(),
  File "/usr/lib/python3.8/json/__init__.py", line 357, in loads
    return _default_decoder.decode(s)
  File "/usr/lib/python3.8/json/decoder.py", line 337, in decode
    obj, end = self.raw_decode(s, idx=_w(s, 0).end())
  File "/usr/lib/python3.8/json/decoder.py", line 355, in raw_decode
    raise JSONDecodeError("Expecting value", s, err.value) from None
json.decoder.JSONDecodeError: Expecting value: line 1 column 13 (char 12)
